2025-04-29 12:21:19,881 - ERROR - Error during crew execution
Traceback (most recent call last):
  File "/Users/aimii/Documents/multi_agent_research_assistant/app.py", line 17, in <module>
    output = run_research(topic)
  File "/Users/aimii/Documents/multi_agent_research_assistant/crew_runner.py", line 15, in run_research
    result = crew.run()
  File "/opt/anaconda3/envs/chatbot_env/lib/python3.10/site-packages/pydantic/main.py", line 994, in __getattr__
    raise AttributeError(f'{type(self).__name__!r} object has no attribute {item!r}')
AttributeError: 'Crew' object has no attribute 'run'
2025-04-29 12:22:37,605 - ERROR - Error during crew execution
Traceback (most recent call last):
  File "/Users/aimii/Documents/multi_agent_research_assistant/app.py", line 17, in <module>
    output = run_research(topic)
  File "/Users/aimii/Documents/multi_agent_research_assistant/crew_runner.py", line 19, in run_research
    result = crew.execute()  # This could be `execute()`, `start()`, or another method depending on the CrewAI library
  File "/opt/anaconda3/envs/chatbot_env/lib/python3.10/site-packages/pydantic/main.py", line 994, in __getattr__
    raise AttributeError(f'{type(self).__name__!r} object has no attribute {item!r}')
AttributeError: 'Crew' object has no attribute 'execute'
2025-04-29 12:27:44,949 - ERROR - Error during crew execution
Traceback (most recent call last):
  File "/Users/aimii/Documents/multi_agent_research_assistant/app.py", line 17, in <module>
    output = run_research(topic)
  File "/Users/aimii/Documents/multi_agent_research_assistant/crew_runner.py", line 21, in run_research
    result = task.run()  # Run each task individually
  File "/opt/anaconda3/envs/chatbot_env/lib/python3.10/site-packages/pydantic/main.py", line 994, in __getattr__
    raise AttributeError(f'{type(self).__name__!r} object has no attribute {item!r}')
AttributeError: 'Task' object has no attribute 'run'
2025-04-29 13:09:19,452 - ERROR - Error during crew execution
Traceback (most recent call last):
  File "/Users/aimii/Documents/multi_agent_research_assistant/app.py", line 17, in <module>
    output = run_research(topic)
  File "/Users/aimii/Documents/multi_agent_research_assistant/crew_runner.py", line 20, in run_research
    results = crew.process_tasks()  # Replace with correct method if CrewAI has one
  File "/opt/anaconda3/envs/chatbot_env/lib/python3.10/site-packages/pydantic/main.py", line 994, in __getattr__
    raise AttributeError(f'{type(self).__name__!r} object has no attribute {item!r}')
AttributeError: 'Crew' object has no attribute 'process_tasks'
2025-04-29 14:35:23,464 - INFO - HTTP Request: POST http://127.0.0.1:11434/api/chat "HTTP/1.1 404 Not Found"
2025-04-29 14:35:23,471 - INFO - HTTP Request: POST http://127.0.0.1:11434/api/chat "HTTP/1.1 404 Not Found"
2025-04-29 14:35:23,477 - INFO - HTTP Request: POST http://127.0.0.1:11434/api/chat "HTTP/1.1 404 Not Found"
2025-04-29 14:35:23,483 - ERROR - Error during crew execution
Traceback (most recent call last):
  File "/Users/aimii/Documents/multi_agent_research_assistant/app.py", line 17, in <module>
    output = run_research(topic)
  File "/Users/aimii/Documents/multi_agent_research_assistant/crew_runner.py", line 22, in run_research
    result = crew.kickoff()
  File "/opt/anaconda3/envs/chatbot_env/lib/python3.10/site-packages/crewai/crew.py", line 649, in kickoff
    result = self._run_sequential_process()
  File "/opt/anaconda3/envs/chatbot_env/lib/python3.10/site-packages/crewai/crew.py", line 761, in _run_sequential_process
    return self._execute_tasks(self.tasks)
  File "/opt/anaconda3/envs/chatbot_env/lib/python3.10/site-packages/crewai/crew.py", line 864, in _execute_tasks
    task_output = task.execute_sync(
  File "/opt/anaconda3/envs/chatbot_env/lib/python3.10/site-packages/crewai/task.py", line 328, in execute_sync
    return self._execute_core(agent, context, tools)
  File "/opt/anaconda3/envs/chatbot_env/lib/python3.10/site-packages/crewai/task.py", line 472, in _execute_core
    raise e  # Re-raise the exception after emitting the event
  File "/opt/anaconda3/envs/chatbot_env/lib/python3.10/site-packages/crewai/task.py", line 392, in _execute_core
    result = agent.execute_task(
  File "/opt/anaconda3/envs/chatbot_env/lib/python3.10/site-packages/crewai/agent.py", line 331, in execute_task
    result = self.execute_task(task, context, tools)
  File "/opt/anaconda3/envs/chatbot_env/lib/python3.10/site-packages/crewai/agent.py", line 331, in execute_task
    result = self.execute_task(task, context, tools)
  File "/opt/anaconda3/envs/chatbot_env/lib/python3.10/site-packages/crewai/agent.py", line 330, in execute_task
    raise e
  File "/opt/anaconda3/envs/chatbot_env/lib/python3.10/site-packages/crewai/agent.py", line 295, in execute_task
    result = self._execute_without_timeout(task_prompt, task)
  File "/opt/anaconda3/envs/chatbot_env/lib/python3.10/site-packages/crewai/agent.py", line 399, in _execute_without_timeout
    return self.agent_executor.invoke(
  File "/opt/anaconda3/envs/chatbot_env/lib/python3.10/site-packages/crewai/agents/crew_agent_executor.py", line 125, in invoke
    raise e
  File "/opt/anaconda3/envs/chatbot_env/lib/python3.10/site-packages/crewai/agents/crew_agent_executor.py", line 112, in invoke
    formatted_answer = self._invoke_loop()
  File "/opt/anaconda3/envs/chatbot_env/lib/python3.10/site-packages/crewai/agents/crew_agent_executor.py", line 221, in _invoke_loop
    raise e
  File "/opt/anaconda3/envs/chatbot_env/lib/python3.10/site-packages/crewai/agents/crew_agent_executor.py", line 155, in _invoke_loop
    answer = get_llm_response(
  File "/opt/anaconda3/envs/chatbot_env/lib/python3.10/site-packages/crewai/utilities/agent_utils.py", line 156, in get_llm_response
    raise e
  File "/opt/anaconda3/envs/chatbot_env/lib/python3.10/site-packages/crewai/utilities/agent_utils.py", line 147, in get_llm_response
    answer = llm.call(
  File "/Users/aimii/Documents/multi_agent_research_assistant/crew_runner.py", line 7, in <lambda>
    LLM.call = lambda self, prompt, *args, **kwargs: call_deepseek(prompt)
  File "/Users/aimii/Documents/multi_agent_research_assistant/deepseek_llm.py", line 12, in call_deepseek
    response = ollama.chat(model='deepseek-coder:latest', messages=messages)
  File "/opt/anaconda3/envs/chatbot_env/lib/python3.10/site-packages/ollama/_client.py", line 333, in chat
    return self._request(
  File "/opt/anaconda3/envs/chatbot_env/lib/python3.10/site-packages/ollama/_client.py", line 178, in _request
    return cls(**self._request_raw(*args, **kwargs).json())
  File "/opt/anaconda3/envs/chatbot_env/lib/python3.10/site-packages/ollama/_client.py", line 122, in _request_raw
    raise ResponseError(e.response.text, e.response.status_code) from None
ollama._types.ResponseError: model "deepseek-coder:latest" not found, try pulling it first (status code: 404)
2025-04-29 14:41:19,931 - INFO - HTTP Request: POST http://127.0.0.1:11434/api/chat "HTTP/1.1 200 OK"
2025-04-29 14:45:02,408 - INFO - HTTP Request: POST http://127.0.0.1:11434/api/chat "HTTP/1.1 200 OK"
2025-04-29 14:47:51,317 - INFO - HTTP Request: GET https://raw.githubusercontent.com/BerriAI/litellm/main/model_prices_and_context_window.json "HTTP/1.1 200 OK"
2025-04-29 14:52:27,666 - INFO - HTTP Request: POST http://127.0.0.1:11434/api/chat "HTTP/1.1 200 OK"
2025-04-29 14:55:24,288 - INFO - HTTP Request: POST http://127.0.0.1:11434/api/chat "HTTP/1.1 200 OK"
2025-04-29 15:00:20,697 - INFO - HTTP Request: POST http://127.0.0.1:11434/api/chat "HTTP/1.1 200 OK"
2025-04-29 15:04:35,745 - INFO - HTTP Request: POST http://127.0.0.1:11434/api/chat "HTTP/1.1 200 OK"
2025-04-29 15:43:51,750 - ERROR - Exception while exporting Span batch.
Traceback (most recent call last):
  File "/opt/anaconda3/envs/chatbot_env/lib/python3.10/site-packages/urllib3/connectionpool.py", line 787, in urlopen
    response = self._make_request(
  File "/opt/anaconda3/envs/chatbot_env/lib/python3.10/site-packages/urllib3/connectionpool.py", line 534, in _make_request
    response = conn.getresponse()
  File "/opt/anaconda3/envs/chatbot_env/lib/python3.10/site-packages/urllib3/connection.py", line 516, in getresponse
    httplib_response = super().getresponse()
  File "/opt/anaconda3/envs/chatbot_env/lib/python3.10/http/client.py", line 1375, in getresponse
    response.begin()
  File "/opt/anaconda3/envs/chatbot_env/lib/python3.10/http/client.py", line 318, in begin
    version, status, reason = self._read_status()
  File "/opt/anaconda3/envs/chatbot_env/lib/python3.10/http/client.py", line 287, in _read_status
    raise RemoteDisconnected("Remote end closed connection without"
http.client.RemoteDisconnected: Remote end closed connection without response

During handling of the above exception, another exception occurred:

Traceback (most recent call last):
  File "/opt/anaconda3/envs/chatbot_env/lib/python3.10/site-packages/requests/adapters.py", line 667, in send
    resp = conn.urlopen(
  File "/opt/anaconda3/envs/chatbot_env/lib/python3.10/site-packages/urllib3/connectionpool.py", line 841, in urlopen
    retries = retries.increment(
  File "/opt/anaconda3/envs/chatbot_env/lib/python3.10/site-packages/urllib3/util/retry.py", line 474, in increment
    raise reraise(type(error), error, _stacktrace)
  File "/opt/anaconda3/envs/chatbot_env/lib/python3.10/site-packages/urllib3/util/util.py", line 38, in reraise
    raise value.with_traceback(tb)
  File "/opt/anaconda3/envs/chatbot_env/lib/python3.10/site-packages/urllib3/connectionpool.py", line 787, in urlopen
    response = self._make_request(
  File "/opt/anaconda3/envs/chatbot_env/lib/python3.10/site-packages/urllib3/connectionpool.py", line 534, in _make_request
    response = conn.getresponse()
  File "/opt/anaconda3/envs/chatbot_env/lib/python3.10/site-packages/urllib3/connection.py", line 516, in getresponse
    httplib_response = super().getresponse()
  File "/opt/anaconda3/envs/chatbot_env/lib/python3.10/http/client.py", line 1375, in getresponse
    response.begin()
  File "/opt/anaconda3/envs/chatbot_env/lib/python3.10/http/client.py", line 318, in begin
    version, status, reason = self._read_status()
  File "/opt/anaconda3/envs/chatbot_env/lib/python3.10/http/client.py", line 287, in _read_status
    raise RemoteDisconnected("Remote end closed connection without"
urllib3.exceptions.ProtocolError: ('Connection aborted.', RemoteDisconnected('Remote end closed connection without response'))

During handling of the above exception, another exception occurred:

Traceback (most recent call last):
  File "/opt/anaconda3/envs/chatbot_env/lib/python3.10/site-packages/opentelemetry/sdk/trace/export/__init__.py", line 362, in _export_batch
    self.span_exporter.export(self.spans_list[:idx])  # type: ignore
  File "/opt/anaconda3/envs/chatbot_env/lib/python3.10/site-packages/opentelemetry/exporter/otlp/proto/http/trace_exporter/__init__.py", line 189, in export
    return self._export_serialized_spans(serialized_data)
  File "/opt/anaconda3/envs/chatbot_env/lib/python3.10/site-packages/opentelemetry/exporter/otlp/proto/http/trace_exporter/__init__.py", line 159, in _export_serialized_spans
    resp = self._export(serialized_data)
  File "/opt/anaconda3/envs/chatbot_env/lib/python3.10/site-packages/opentelemetry/exporter/otlp/proto/http/trace_exporter/__init__.py", line 133, in _export
    return self._session.post(
  File "/opt/anaconda3/envs/chatbot_env/lib/python3.10/site-packages/requests/sessions.py", line 637, in post
    return self.request("POST", url, data=data, json=json, **kwargs)
  File "/opt/anaconda3/envs/chatbot_env/lib/python3.10/site-packages/requests/sessions.py", line 589, in request
    resp = self.send(prep, **send_kwargs)
  File "/opt/anaconda3/envs/chatbot_env/lib/python3.10/site-packages/requests/sessions.py", line 703, in send
    r = adapter.send(request, **kwargs)
  File "/opt/anaconda3/envs/chatbot_env/lib/python3.10/site-packages/requests/adapters.py", line 682, in send
    raise ConnectionError(err, request=request)
requests.exceptions.ConnectionError: ('Connection aborted.', RemoteDisconnected('Remote end closed connection without response'))
2025-04-29 15:48:58,573 - INFO - HTTP Request: POST http://127.0.0.1:11434/api/chat "HTTP/1.1 200 OK"
2025-04-29 15:52:41,773 - INFO - HTTP Request: POST http://127.0.0.1:11434/api/chat "HTTP/1.1 200 OK"
2025-04-29 15:56:25,757 - INFO - HTTP Request: POST http://127.0.0.1:11434/api/chat "HTTP/1.1 200 OK"
2025-04-29 16:00:59,780 - INFO - HTTP Request: POST http://127.0.0.1:11434/api/chat "HTTP/1.1 200 OK"
